<mujocoinclude>
  <body name="dClaw" euler="3.14 0 0" childclass="dclaw3xh">
    <geom material="acrylic" mesh="acrylic_circle"/>
    <geom class="phy_metal" type="cylinder" size="0.75 0.04" mass="1.1"/>
    <site name="S_grasp" pos="0 0 2.4" type="sphere" size="0.1" group="4"/>

    <!-- INDEX/FIRST FINGER -->
    <body name="FFbase" pos=".3 -0.52 .03" euler="0 0 .52">
      <geom mesh="xh28" pos="0 0 0.1425" euler="1.57 0 1.57"/>
      <geom class="phy_metal" type="box" pos=".12 0 0.14" size="0.24 0.175 0.15" mass="0.93"/>
      <body name="FF10" pos="0 0 0.1425" euler="0 0 3.14">
        <geom mesh="metal_clamping" euler="0 0 1.57"/>
        <geom mesh="metal_clamping_small" pos="0 0 0.55" euler="3.14 0 0"/>
        <geom mesh="xh28" pos="0 0 0.68" euler="1.57 1.57 0"/>
        <geom class="phy_metal" type="box" pos="0 0 0.56" size="0.175 0.15 0.24" mass="0.93"/>
        <geom class="phy_metal" type="box" pos="0.0 0 0.26" size="0.125 0.214 0.03" mass="0.03"/>
        <geom class="phy_metal" type="box" pos="0 0.2 0.13" size="0.11 0.012 0.16" mass="0.02"/>
        <geom class="phy_metal" type="box" pos="0 -0.2 0.13" size="0.11 0.012 0.16" mass="0.02"/>
        <geom class="phy_metal" type="box" pos="0 0 0.33" size="0.19 0.14 0.06" mass="0.05"/>
        <joint name="FFJ10" type="hinge" axis="0 1 0" range="-4.5 13.5"/>
        <body name="FFL11" pos="0 0 0.675">
          <geom mesh="metal_clamping_small" pos="0 0 0.55" euler="3.14 0 0"/>
          <geom mesh="xh28" pos="0 0 0.686" euler="1.57 1.57 0"/>
          <geom mesh="metal_clamping"/>
          <geom class="phy_metal" type="box" pos="0 0 0.56" size="0.175 0.15 0.24" mass="0.93"/>
          <geom class="phy_metal" type="box" pos="0 0 0.26" size="0.214 0.125 0.03" mass="0.03"/>
          <geom class="phy_metal" type="box" pos="0.2 0 0.13" size="0.012 0.11 0.16" mass="0.20"/>
          <geom class="phy_metal" type="box" pos="-0.2 0 0.13" size="0.012 0.11 0.16" mass="0.02"/>
          <geom class="phy_metal" type="box" pos="0 0 0.33" size="0.19 0.14 0.06" mass="0.5"/>
          <joint name="FFJ11" type="hinge" axis="1 0 0" range="-2 2"/>
          <body name="FFL12" pos="0 0 0.68">
            <geom mesh="metal_clamping"/>
            <geom material="plastic" mesh="plastic_finger" pos="0 0 0.46"/>
            <geom class="phy_metal" type="box" pos="0.0 0 0.26" size="0.214 0.125 0.03" mass="0.03"/>
            <geom class="phy_metal" type="box" pos="0.2 0 0.13" size="0.012 0.11 0.16" mass="0.02"/>
            <geom class="phy_metal" type="box" pos="-0.2 0 0.13" size="0.012 0.11 0.16" mass="0.02"/>
            <geom class="phy_plastic" type="capsule" pos="0 0 0.53" size="0.11 0.2" mass="0.18"/>
            <geom class="phy_plastic" type="box" pos="0 0 0.3" size="0.245 0.14 0.03" mass="0.07"/>
            <joint name="FFJ12" type="hinge" axis="1 0 0" range="-2 2"/>
            <site name="FFtip" type="sphere" pos="0 0 .76" size="0.1" rgba="1 .3 .3 1"/>
          </body>
        </body>
      </body>
    </body>
  </body>
</mujocoinclude>
